Workbook

Sheet Feb-25
C2: CHUDLEIGH HOUSE SCHOOL STAFF LEAVE DAYS
C3: FOR THE MONTH OF FEBRUARY 2025
C4: NAME | D4: POSITION | E4: OPENING | F4: DAYS EARNED | G4: TOTAL | H4: DAYS TAKEN | I4: NET
B5: 1 | C5: ABBY PHIRI | D5: Financial Controller | E5: 25 | F5: 2 | G5: =E5+F5 -> 27 | H5: 1 | I5: =G5-H5 -> 26
B6: 2 | C6: Margaret Mukondwa | D6: Executive Assistant | E6: 133 | F6: 2 | G6: =E6+F6 -> 135 | H6: 0 | I6: =G6-H6 -> 135
B7: 3 | C7: mizzie Mutambo | D7: ass. Accountant | E7: 38 | F7: 2 | G7: =E7+F7 -> 40 | H7: 0 | I7: =G7-H7 -> 40
B8: 4 | C8: Tembo Bertha | D8: teacher Primary | E8: 2 | F8: 2 | G8: =E8+F8 -> 4 | H8: 0 | I8: =G8-H8 -> 4
B9: 5 | C9: Kamanugu Mriiam | D9: Teacher Primary | E9: 2 | F9: 2 | G9: =E9+F9 -> 4 | H9: 0 | I9: =G9-H9 -> 4
B10: 6 | C10: Chisenga Gillian Mwambela | D10: teacher Primary | E10: 2 | F10: 2 | G10: =E10+F10 -> 4 | H10: 0 | I10: =G10-H10 -> 4
B11: 7 | C11: Nambela Mercy | D11: teacher Primary | E11: 2 | F11: 2 | G11: =E11+F11 -> 4 | H11: 2 | I11: =G11-H11 -> 2
B12: 8 | C12: Mutale Mirram | D12: teacher Primary | E12: 27 | F12: 2 | G12: =E12+F12 -> 29 | H12: 0 | I12: =G12-H12 -> 29
B13: 9 | C13: Zimba Francisca | D13: teacher Primary | E13: 2 | F13: 2 | G13: =E13+F13 -> 4 | H13: 0 | I13: =G13-H13 -> 4
B14: 10 | C14: Ireen Nachinga | D14: teacher Primary | E14: 2 | F14: 2 | G14: =E14+F14 -> 4 | H14: 0 | I14: =G14-H14 -> 4
B15: 11 | C15: Munyati Senitor | D15: PCELC - Teacher | E15: 2 | F15: 2 | G15: =E15+F15 -> 4 | H15: 0 | I15: =G15-H15 -> 4
B16: 12 | C16: Banda Mary | D16: PCELC- Teacher | E16: 2 | F16: 2 | G16: =E16+F16 -> 4 | H16: 0 | I16: =G16-H16 -> 4
... B103: 99 | C103: Memory Phiri | D103: Primary | E103: 2 | F103: 2 | G103: =E103+F103 -> 4 | H103: 0 | I103: =G103-H103 -> 4
B104: 100 | C104: Nkhowani Francis | D104: Security | E104: 0 | F104: 2 | G104: =E104+F104 -> 2 | I104: =G104-H104 -> 2
B105: 101 | C105: Mwape Chongo | D105: Primary | E105: 0 | F105: 2 | G105: =E105+F105 -> 2 | H105: 0 | I105: =G105-H105 -> 2
B106: 102 | C106: Mwenya Bruce | D106: Security | E106: 0 | F106: 2 | G106: =E106+F106 -> 2 | H106: 0 | I106: =G106-H106 -> 2
B107: 103 | C107: Richard Chilekwa | D107: Security | E107: 38 | F107: 2 | G107: =E107+F107 -> 40 | H107: 0 | I107: =G107-H107 -> 40
B108: 104 | C108: faides Daka | D108: security | E108: 24 | F108: 2 | G108: =E108+F108 -> 26 | H108: 1 | I108: =G108-H108 -> 25
B109: 105 | C109: Gift Kapalayi | D109: Security | E109: 37 | F109: 2 | G109: =E109+F109 -> 39 | H109: 0 | I109: =G109-H109 -> 39
B110: 106 | C110: Levy Ingwe | D110: Security | E110: 117 | F110: 2 | G110: =E110+F110 -> 119 | H110: 0 | I110: =G110-H110 -> 119
B111: 107 | C111: zulu Anderson | D111: Security | E111: 105 | F111: 2 | G111: =E111+F111 -> 107 | H111: 40 | I111: =G111-H111 -> 67
B112: 108 | C112: Sholobela Abigail | D112: Security Officer | E112: 38 | F112: 2 | G112: =E112+F112 -> 40 | H112: 0 | I112: =G112-H112 -> 40
B113: 109 | C113: sley Banda | D113: Driver | E113: 4 | F113: 2 | G113: =E113+F113 -> 6 | H113: 0 | I113: =G113-H113 -> 6
B114: 110 | C114: Douglas Soko | D114: Teacher Secondary | E114: 2 | F114: 2 | G114: =E114+F114 -> 4 | H114: 0 | I114: =G114-H114 -> 4
B115: 111 | C115: chama Mathews | D115: general Works | E115: 108 | F115: 2 | G115: =E115+F115 -> 110 | H115: 0 | I115: =G115-H115 -> 110
B116: 112 | C116: Mirriam Kamangu | D116: Teacher Primary | E116: 2 | F116: 2 | G116: =E116+F116 -> 4 | H116: 0 | I116: =G116-H116 -> 4
... B121: 118 | C121: nyemba Lwamba | D121: PE teacher | E121: 2 | F121: 2 | G121: =E121+F121 -> 4 | H121: 0 | I121: =G121-H121 -> 4
B122: 119 | C122: Mandona Kangwa | D122: Librarian | E122: 2 | F122: 2 | G122: 0 | H122: 0 | I122: =G122-H122 -> 0
B123: 120 | C123: Katabwa Osward | D123: Secondary | E123: 6 | F123: 2 | G123: =E123+F123 -> 8 | H123: 0 | I123: =G123-H123 -> 8
B124: 123 | C124: Chakufyali Victor | D124: Primary | E124: 2 | F124: 2 | G124: =E124+F124 -> 4 | H124: 0 | I124: =G124-H124 -> 4
B125: 124 | C125: Memory Phiri | D125: Primary | E125: 11 | F125: 2 | G125: =E125+F125 -> 13 | H125: 0 | I125: =G125-H125 -> 13
B126: 125 | C126: Mumba Limpo | D126: Primary | E126: 8 | F126: 0 | G126: =E126+F126 -> 8 | H126: 0 | I126: =G126-H126 -> 8
B127: 126 | C127: Mwape Chongo | D127: Primary | E127: 34 | F127: 2 | G127: =E127+F127 -> 36 | H127: 0 | I127: =G127-H127 -> 36
B128: 127 | C128: kashumba Christabel | D128: Primary | E128: 20 | F128: 2 | G128: =E128+F128 -> 22 | H128: 0 | I128: =G128-H128 -> 22
B129: 128 | C129: Richard Chilekwa | D129: Security | E129: 57 | F129: 2 | G129: =E129+F129 -> 59 | H129: 0 | I129: =G129-H129 -> 59
B130: 129 | C130: Robert Lungu | D130: Driver | E130: 0 | F130: 2 | G130: =E130+F130 -> 2 | H130: 0 | I130: =G130-H130 -> 2
B131: 130 | C131: Gift Kapalayi | D131: Security | E131: 82 | F131: 0 | G131: =E131+F131 -> 82 | H131: 0 | I131: =G131-H131 -> 82
...

Sheet Mar-25
B2: CHUDLEIGH HOUSE SCHOOL STAFF LEAVE DAYS
B3: FOR THE MONTH OF MARCH 2022
B4: NAME | C4: POSITION | D4: OPENING | E4: DAYS EARNED | F4: TOTAL | G4: DAYS TAKEN | H4: NET
A5: 1 | B5: ABBY PHIRI | C5: Financial Controller | D5: 26 | E5: 2 | F5: =D5+E5 -> 28 | H5: =F5-G5 -> 28
A6: 2 | B6: Margaret Mukondwa | C6: Executive Assistant | D6: 135 | E6: 2 | F6: =D6+E6 -> 137 | G6: 6 | H6: =F6-G6 -> 131
A7: 3 | B7: mizzie Mutambo | C7: ass. Accountant | D7: 40 | E7: 2 | F7: =D7+E7 -> 42 | H7: =F7-G7 -> 42
A8: 4 | B8: Tembo Bertha | C8: teacher Primary | D8: 4 | E8: 2 | F8: =D8+E8 -> 6 | H8: =F8-G8 -> 6
A9: 5 | B9: Kamanugu Mriiam | C9: Teacher Primary | D9: 4 | E9: 2 | F9: =D9+E9 -> 6 | H9: =F9-G9 -> 6
A10: 6 | B10: Chisenga Gillian Mwambela | C10: teacher Primary | D10: 4 | E10: 2 | F10: =D10+E10 -> 6 | H10: =F10-G10 -> 6
A11: 7 | B11: Nambela Mercy | C11: teacher Primary | D11: 4 | E11: 2 | F11: =D11+E11 -> 6 | G11: 12 | H11: =F11-G11 -> -6
A12: 8 | D12: 0 | E12: 2 | F12: =D12+E12 -> 2 | H12: =F12-G12 -> 2
A13: 9 | B13: Zimba Francisca | C13: teacher Primary | D13: 4 | E13: 2 | F13: =D13+E13 -> 6 | H13: =F13-G13 -> 6
A14: 10 | B14: Ireen Nachinga | C14: teacher Primary | D14: 4 | E14: 2 | F14: =D14+E14 -> 6 | H14: =F14-G14 -> 6
A15: 11 | B15: Munyati Senitor | C15: PCELC - Teacher | D15: 4 | E15: 2 | F15: =D15+E15 -> 6 | H15: =F15-G15 -> 6
A16: 12 | B16: Banda Mary | C16: PCELC- Teacher | D16: 4 | E16: 2 | F16: =D16+E16 -> 6 | H16: =F16-G16 -> 6
A17: 13 | B17: Mwanida Jere | C17: PCELC- Teacher | D17: 4 | E17: 2 | F17: =D17+E17 -> 6 | H17: =F17-G17 -> 6
A18: 14 | B18: George Kakoma | C18: Cashier | D18: 19 | E18: 2 | F18: =D18+E18 -> 21 | H18: =F18-G18 -> 21
A19: 15 | B19: Masebo Hudson | C19: School Bursar | D19: 104 | E19: 2 | F19: =D19+E19 -> 106 | H19: =F19-G19 -> 106
A20: 16 | B20: Nancy nanyangwe | C20: Cashier | D20: 69 | E20: 2 | F20: =D20+E20 -> 71 | H20: =F20-G20 -> 71
A21: 17 | B21: samuel Chinyama | C21: Teacher | D21: 6 | E21: 2 | F21: =D21+E21 -> 8 | H21: =F21-G21 -> 8
A22: 18 | B22: besa Godfrey | C22: Senior Techer | D22: 8 | E22: 2 | F22: =D22+E22 -> 10 | H22: =F22-G22 -> 10
A23: 19 | B23: Mario Kambani | C23: General Works | D23: 15 | E23: 2 | F23: =D23+E23 -> 17 | H23: =F23-G23 -> 17
A24: 20 | D24: 0 | E24: 2 | F24: =D24+E24 -> 2 | H24: =F24-G24 -> 2
A25: 21 | B25: Timothy Phiri | C25: General Works | D25: 20 | E25: 2 | F25: =D25+E25 -> 22 | H25: =F25-G25 -> 22
A26: 22 | B26: Winnie Sishwani | C26: Teacher Secondary | D26: 7 | E26: 2 | F26: =D26+E26 -> 9 | H26: =F26-G26 -> 9
A27: 23 | B27: Valentine Zulu | C27: Teacher Secondary | D27: 4 | E27: 2 | F27: =D27+E27 -> 6 | H27: =F27-G27 -> 6
A28: 24 | B28: Tembo Diana | C28: lib Assitant | D28: 12 | E28: 2 | F28: =D28+E28 -> 14 | H28: =F28-G28 -> 14
A29: 25 | D29: 0 | E29: 2 | F29: =D29+E29 -> 2 | H29: =F29-G29 -> 2
A30: 26 | B30: Anderson Ngulube | C30: Secondary | D30: 4 | E30: 2 | F30: =D30+E30 -> 6 | H30: =F30-G30 -> 6
A31: 27 | D31: 0 | E31: 2 | F31: =D31+E31 -> 2 | H31: =F31-G31 -> 2
A32: 28 | B32: kalongana Nyambe | C32: security | D32: 89 | E32: 2 | F32: =D32+E32 -> 91 | H32: =F32-G32 -> 91
A33: 29 | B33: Namakala Mackenzie | C33: Primary Head | D33: 16 | E33: 2 | F33: =D33+E33 -> 18 | H33: =F33-G33 -> 18
A34: 30 | B34: Mashewa Alice | C34: Primary | D34: 4 | E34: 2 | F34: =D34+E34 -> 6 | H34: =F34-G34 -> 6
A35: 31 | B35: Rose Daka | C35: PCELC | D35: 4 | E35: 2 | F35: =D35+E35 -> 6 | G35: 1 | H35: =F35-G35 -> 5
A36: 32 | B36: priscilla Muluso | C36: primary | D36: 4 | E36: 2 | F36: =D36+E36 -> 6 | H36: =F36-G36 -> 6
A37: 33 | B37: Banda Esther | C37: prmary | D37: 4 | E37: 2 | F37: =D37+E37 -> 6 | H37: =F37-G37 -> 6
A38: 34 | B38: beatrice Kasuka | C38: General works | D38: 48 | E38: 2 | F38: =D38+E38 -> 50 | H38: =F38-G38 -> 50
A39: 35 | B39: gwaba Mweemba | C39: Head Secondary | D39: 34 | E39: 2 | F39: =D39+E39 -> 36 | H39: =F39-G39 -> 36
A40: 36 | B40: caleb Simuchimba | C40: Secondary | D40: 4 | E40: 2 | F40: =D40+E40 -> 6 | H40: =F40-G40 -> 6
A41: 37 | B41: Kabemba Kim Kabemba | C41: Primary | D41: 4 | E41: 2 | F41: =D41+E41 -> 6 | H41: =F41-G41 -> 6
...

Sheet Apr-25
B2: CHUDLEIGH HOUSE SCHOOL STAFF LEAVE DAYS
B3: NAME | C3: POSITION
A4: 1 | B4: ABBY PHIRI | C4: Financial Controller | D4: OPENING | E4: DAYS EARNED | F4: TOTAL | G4: DAYS TAKEN | H4: NET
A5: 2 | B5: Margaret Mukondwa | C5: Executive Assistant | D5: 28 | E5: 2 | F5: =D5+E5 -> 30 | G5: 0 | H5: =F5-G5 -> 30
A6: 3 | B6: mizzie Mutambo | C6: ass. Accountant | D6: 137 | E6: 2 | F6: =D6+E6 -> 139 | G6: 0 | H6: =F6-G6 -> 139
A7: 4 | B7: Tembo Bertha | C7: teacher Primary | D7: 42 | E7: 2 | F7: =D7+E7 -> 44 | G7: 0 | H7: =F7-G7 -> 44
A8: 5 | B8: Kamanugu Mriiam | C8: Teacher Primary | D8: 6 | E8: 2 | F8: =D8+E8 -> 8 | G8: 8 | H8: =F8-G8 -> 0
A9: 6 | B9: Chisenga Gillian Mwambela | C9: teacher Primary | D9: 6 | E9: 2 | F9: =D9+E9 -> 8 | G9: 8 | H9: =F9-G9 -> 0
A10: 7 | B10: Nambela Mercy | C10: teacher Primary | D10: 6 | E10: 2 | F10: =D10+E10 -> 8 | G10: 8 | H10: =F10-G10 -> 0
A11: 8 | D11: -6 | E11: 2 | F11: =D11+E11 -> -4 | G11: 0 | H11: =F11-G11 -> -4
A12: 9 | B12: Zimba Francisca | C12: teacher Primary | D12: 2 | E12: 2 | F12: =D12+E12 -> 4 | G12: 8 | H12: =F12-G12 -> -4
A13: 10 | B13: Ireen Nachinga | C13: teacher Primary | D13: 6 | E13: 2 | F13: =D13+E13 -> 8 | G13: 8 | H13: =F13-G13 -> 0
A14: 11 | B14: Munyati Senitor | C14: PCELC - Teacher | D14: 6 | E14: 2 | F14: =D14+E14 -> 8 | G14: 8 | H14: =F14-G14 -> 0
A15: 12 | B15: Banda Mary | C15: PCELC- Teacher | D15: 6 | E15: 2 | F15: =D15+E15 -> 8 | G15: 0 | H15: =F15-G15 -> 8
A16: 13 | B16: Mwanida Jere | C16: PCELC- Teacher | D16: 6 | E16: 2 | F16: =D16+E16 -> 8 | G16: 8 | H16: =F16-G16 -> 0
A17: 14 | B17: George Kakoma | C17: Cashier | D17: 6 | E17: 2 | F17: =D17+E17 -> 8 | G17: 14 | H17: =F17-G17 -> -6
A18: 15 | B18: Masebo Hudson | C18: School Bursar | D18: 21 | E18: 2 | F18: =D18+E18 -> 23 | G18: 0 | H18: =F18-G18 -> 23
A19: 16 | B19: Nancy nanyangwe | C19: Cashier | D19: 106 | E19: 2 | F19: =D19+E19 -> 108 | G19: 9 | H19: =F19-G19 -> 99
A20: 17 | B20: samuel Chinyama | C20: Teacher | D20: 8 | E20: 2 | F20: =D20+E20 -> 10 | G20: 8 | H20: =F20-G20 -> 2
A21: 18 | B21: besa Godfrey | C21: Senior Techer | D21: 8 | E21: 2 | F21: =D21+E21 -> 10 | G21: 8 | H21: =F21-G21 -> 2
A22: 19 | B22: Mario Kambani | C22: General Works | D22: 10 | E22: 2 | F22: =D22+E22 -> 12 | G22: 11 | H22: =F22-G22 -> 1
A23: 20 | D23: 17 | E23: 2 | F23: =D23+E23 -> 19 | G23: 0 | H23: =F23-G23 -> 19
A24: 21 | B24: Timothy Phiri | C24: General Works | D24: 2 | E24: 2 | F24: =D24+E24 -> 4 | G24: 2 | H24: =F24-G24 -> 2
A25: 22 | B25: Winnie Sishwani | C25: Teacher Secondary | D25: 22 | E25: 2 | F25: =D25+E25 -> 24 | G25: 0 | H25: =F25-G25 -> 24
A26: 23 | B26: Valentine Zulu | C26: Teacher Secondary | D26: 6 | E26: 2 | F26: =D26+E26 -> 8 | G26: 8 | H26: =F26-G26 -> 0
A27: 24 | B27: Tembo Diana | C27: lib Assitant | D27: 6 | E27: 2 | F27: =D27+E27 -> 8 | G27: 0 | H27: =F27-G27 -> 8
A28: 25 | D28: 14 | E28: 2 | F28: =D28+E28 -> 16 | G28: 0 | H28: =F28-G28 -> 16
A29: 26 | B29: Anderson Ngulube | C29: Secondary | D29: 6 | E29: 2 | F29: =D29+E29 -> 8 | G29: 8 | H29: =F29-G29 -> 0
A30: 27 | D30: 6 | E30: 2 | F30: =D30+E30 -> 8 | G30: 0 | H30: =F30-G30 -> 8
A31: 28 | B31: kalongana Nyambe | C31: security | D31: 2 | E31: 2 | F31: =D31+E31 -> 4 | G31: 0 | H31: =F31-G31 -> 4
A32: 29 | B32: Namakala Mackenzie | C32: Primary Head | D32: 91 | E32: 2 | F32: =D32+E32 -> 93 | G32: 1 | H32: =F32-G32 -> 92
A33: 30 | B33: Mashewa Alice | C33: Primary | D33: 18 | E33: 2 | F33: =D33+E33 -> 20 | G33: 0 | H33: =F33-G33 -> 20
A34: 31 | B34: Rose Daka | C34: PCELC | D34: 6 | E34: 2 | F34: =D34+E34 -> 8 | G34: 8 | H34: =F34-G34 -> 0
A35: 32 | B35: priscilla Muluso | C35: primary | D35: 5 | E35: 2 | F35: =D35+E35 -> 7 | G35: 0 | H35: =F35-G35 -> 7
A36: 33 | B36: Banda Esther | C36: prmary | D36: 6 | E36: 2 | F36: =D36+E36 -> 8 | G36: 8 | H36: =F36-G36 -> 0
A37: 34 | B37: beatrice Kasuka | C37: General works | D37: 6 | E37: 2 | F37: =D37+E37 -> 8 | G37: 8 | H37: =F37-G37 -> 0
A38: 35 | B38: gwaba Mweemba | C38: Head Secondary | D38: 50 | E38: 2 | F38: =D38+E38 -> 52 | H38: =F38-G38 -> 52
A39: 36 | B39: caleb Simuchimba | C39: Secondary | D39: 36 | E39: 2 | F39: =D39+E39 -> 38 | G39: 0 | H39: =F39-G39 -> 38
A40: 37 | B40: Kabemba Kim Kabemba | C40: Primary | D40: 6 | E40: 2 | F40: =D40+E40 -> 8 | G40: 8 | H40: =F40-G40 -> 0
A41: 38 | B41: mtonga camila | C41: Primary | D41: 6 | E41: 2 | F41: =D41+E41 -> 8 | G41: 8 | H41: =F41-G41 -> 0
...

Sheet May-25
C1: CHUDLEIGH HOUSE SCHOOL STAFF LEAVE DAYS
B4: NAME | C4: POSITION | D4: NET | E4: DAYS EARNED | F4: TOTAL | G4: DAYS TAKEN | H4: NET
A5: 1 | B5: ABBY PHIRI | C5: Financial Controller | D5: 30 | E5: 2 | F5: =D5+E5 -> 32 | H5: =F5-G5 -> 32
A6: 2 | B6: Margaret Mukondwa | C6: Executive Assistant | D6: 139 | E6: 2 | F6: =D6+E6 -> 141 | H6: =F6-G6 -> 141
A7: 3 | B7: mizzie Mutambo | C7: ass. Accountant | D7: 44 | E7: 2 | F7: =D7+E7 -> 46 | H7: =F7-G7 -> 46
A8: 4 | B8: Tembo Bertha | C8: teacher Primary | D8: 0 | E8: 2 | F8: =D8+E8 -> 2 | H8: =F8-G8 -> 2
A9: 5 | B9: Kamanugu Mriiam | C9: Teacher Primary | D9: 0 | E9: 2 | F9: =D9+E9 -> 2 | H9: =F9-G9 -> 2
A10: 6 | B10: Chisenga Gillian Mwambela | C10: teacher Primary | D10: 0 | E10: 2 | F10: =D10+E10 -> 2 | H10: =F10-G10 -> 2
A11: 7 | B11: Nambela Mercy | C11: teacher Primary | D11: 0 | E11: 2 | F11: =D11+E11 -> 2 | H11: =F11-G11 -> 2
A12: 8 | D12: -4 | E12: 2 | F12: =D12+E12 -> -2 | H12: =F12-G12 -> -2
A13: 9 | B13: Zimba Francisca | C13: teacher Primary | D13: 0 | E13: 2 | F13: =D13+E13 -> 2 | H13: =F13-G13 -> 2
A14: 10 | B14: Ireen Nachinga | C14: teacher Primary | D14: 0 | E14: 2 | F14: =D14+E14 -> 2 | H14: =F14-G14 -> 2
A15: 11 | B15: Munyati Senitor | C15: PCELC - Teacher | D15: 0 | E15: 2 | F15: =D15+E15 -> 2 | H15: =F15-G15 -> 2
A16: 12 | B16: Banda Mary | C16: PCELC- Teacher | D16: 8 | E16: 2 | F16: =D16+E16 -> 10 | H16: =F16-G16 -> 10
A17: 13 | B17: Mwanida Jere | C17: PCELC- Teacher | D17: 0 | E17: 2 | F17: =D17+E17 -> 2 | H17: =F17-G17 -> 2
A18: 14 | B18: George Kakoma | C18: Cashier | D18: 23 | E18: 2 | F18: =D18+E18 -> 25 | H18: =F18-G18 -> 25
A19: 15 | B19: Masebo Hudson | C19: School Bursar | D19: 99 | E19: 2 | F19: =D19+E19 -> 101 | H19: =F19-G19 -> 101
A20: 16 | B20: Nancy nanyangwe | C20: Cashier | D20: 73 | E20: 2 | F20: =D20+E20 -> 75 | H20: =F20-G20 -> 75
A21: 17 | B21: samuel Chinyama | C21: Teacher | D21: 2 | E21: 2 | F21: =D21+E21 -> 4 | H21: =F21-G21 -> 4
A22: 18 | B22: besa Godfrey | C22: Senior Techer | D22: 1 | E22: 2 | F22: =D22+E22 -> 3 | H22: =F22-G22 -> 3
A23: 19 | B23: Mario Kambani | C23: General Works | D23: 19 | E23: 2 | F23: =D23+E23 -> 21 | H23: =F23-G23 -> 21
A24: 20 | D24: 2 | E24: 2 | F24: =D24+E24 -> 4 | H24: =F24-G24 -> 4
A25: 21 | B25: Timothy Phiri | C25: General Works | D25: 24 | E25: 2 | F25: =D25+E25 -> 26 | H25: =F25-G25 -> 26
A26: 22 | B26: Winnie Sishwani | C26: Teacher Secondary | D26: 3 | E26: 2 | F26: =D26+E26 -> 5 | H26: =F26-G26 -> 5
A27: 23 | B27: Valentine Zulu | C27: Teacher Secondary | D27: 0 | E27: 2 | F27: =D27+E27 -> 2 | H27: =F27-G27 -> 2
A28: 24 | B28: Tembo Diana | C28: lib Assitant | D28: 16 | E28: 2 | F28: =D28+E28 -> 18 | H28: =F28-G28 -> 18
A29: 25 | D29: 4 | E29: 2 | F29: =D29+E29 -> 6 | H29: =F29-G29 -> 6
A30: 26 | B30: Anderson Ngulube | C30: Secondary | D30: 0 | E30: 2 | F30: =D30+E30 -> 2 | H30: =F30-G30 -> 2
A31: 27 | D31: 4 | E31: 2 | F31: =D31+E31 -> 6 | H31: =F31-G31 -> 6
A32: 28 | B32: kalongana Nyambe | C32: security | D32: 92 | E32: 2 | F32: =D32+E32 -> 94 | H32: =F32-G32 -> 94
A33: 29 | B33: Namakala Mackenzie | C33: Primary Head | D33: 20 | E33: 2 | F33: =D33+E33 -> 22 | H33: =F33-G33 -> 22
A34: 30 | B34: Mashewa Alice | C34: Primary | D34: 0 | E34: 2 | F34: =D34+E34 -> 2 | H34: =F34-G34 -> 2
A35: 31 | B35: Rose Daka | C35: PCELC | D35: 0 | E35: 2 | F35: =D35+E35 -> 2 | H35: =F35-G35 -> 2
A36: 32 | B36: priscilla Muluso | C36: primary | D36: 0 | E36: 2 | F36: =D36+E36 -> 2 | H36: =F36-G36 -> 2
A37: 33 | B37: Banda Esther | C37: prmary | D37: 0 | E37: 2 | F37: =D37+E37 -> 2 | H37: =F37-G37 -> 2
A38: 34 | B38: beatrice Kasuka | C38: General works | D38: 52 | E38: 2 | F38: =D38+E38 -> 54 | H38: =F38-G38 -> 54
A39: 35 | B39: gwaba Mweemba | C39: Head Secondary | D39: 38 | E39: 2 | F39: =D39+E39 -> 40 | H39: =F39-G39 -> 40
A40: 36 | B40: caleb Simuchimba | C40: Secondary | D40: 0 | E40: 2 | F40: =D40+E40 -> 2 | H40: =F40-G40 -> 2
A41: 37 | B41: Kabemba Kim Kabemba | C41: Primary | D41: 0 | E41: 2 | F41: =D41+E41 -> 2 | H41: =F41-G41 -> 2
A42: 38 | B42: mtonga camila | C42: Primary | D42: 0 | E42: 2 | F42: =D42+E42 -> 2 | H42: =F42-G42 -> 2
...

Sheet Jun-25
C2: CHUDLEIGH HOUSE SCHOOL STAFF LEAVE DAYS
C3: FOR THE MONTH OF FEBRUARY 2022
B4: NAME | C4: POSITION | D4: OPENING | E4: DAYS EARNED | F4: TOTAL | G4: DAYS TAKEN | H4: NET
A5: 1 | B5: ABBY PHIRI | C5: Financial Controller | D5: 32 | E5: 2 | F5: =D5+E5 -> 34 | G5: 3 | H5: =F5-G5 -> 31
A6: 2 | B6: Margaret Mukondwa | C6: Executive Assistant | D6: 141 | E6: 2 | F6: =D6+E6 -> 143 | G6: 11 | H6: =F6-G6 -> 132
A7: 3 | B7: mizzie Mutambo | C7: ass. Accountant | D7: 46 | E7: 2 | F7: =D7+E7 -> 48 | H7: =F7-G7 -> 48
A8: 4 | B8: Tembo Bertha | C8: teacher Primary | D8: 2 | E8: 2 | F8: =D8+E8 -> 4 | G8: 1 | H8: =F8-G8 -> 3
A9: 5 | B9: Kamanugu Mriiam | C9: Teacher Primary | D9: 2 | E9: 2 | F9: =D9+E9 -> 4 | H9: =F9-G9 -> 4
A10: 6 | B10: Chisenga Gillian Mwambela | C10: teacher Primary | D10: 2 | E10: 2 | F10: =D10+E10 -> 4 | H10: =F10-G10 -> 4
A11: 7 | B11: Nambela Mercy | C11: teacher Primary | D11: 2 | E11: 2 | F11: =D11+E11 -> 4 | H11: =F11-G11 -> 4
A12: 8 | B12: Nakache Chewe | C12: Teacher Primary | D12: 2 | E12: 2 | F12: =D12+E12 -> 4 | H12: =F12-G12 -> 4
A13: 9 | B13: Zimba Francisca | C13: teacher Primary | D13: 2 | E13: 2 | F13: =D13+E13 -> 4 | H13: =F13-G13 -> 4
A14: 10 | B14: Ireen Nachinga | C14: teacher Primary | D14: 2 | E14: 2 | F14: =D14+E14 -> 4 | H14: =F14-G14 -> 4
A15: 11 | B15: Munyati Senitor | C15: PCELC - Teacher | D15: 2 | E15: 2 | F15: =D15+E15 -> 4 | G15: 1 | H15: =F15-G15 -> 3
A16: 12 | B16: Banda Mary | C16: PCELC- Teacher | D16: 10 | E16: 2 | F16: =D16+E16 -> 12 | H16: =F16-G16 -> 12
A17: 13 | B17: Mwanida Jere | C17: PCELC- Teacher | D17: 2 | E17: 2 | F17: =D17+E17 -> 4 | H17: =F17-G17 -> 4
A18: 14 | B18: George Kakoma | C18: Cashier | D18: 25 | E18: 2 | F18: =D18+E18 -> 27 | H18: =F18-G18 -> 27
A19: 15 | B19: Masebo Hudson | C19: School Bursar | D19: 101 | E19: 2 | F19: =D19+E19 -> 103 | H19: =F19-G19 -> 103
A20: 16 | B20: Nancy nanyangwe | C20: Cashier | D20: 75 | E20: 2 | F20: =D20+E20 -> 77 | H20: =F20-G20 -> 77
A21: 17 | B21: samuel Chinyama | C21: Teacher | D21: 4 | E21: 2 | F21: =D21+E21 -> 6 | H21: =F21-G21 -> 6
A22: 18 | B22: besa Godfrey | C22: Senior Techer | D22: 3 | E22: 2 | F22: =D22+E22 -> 5 | H22: =F22-G22 -> 5
A23: 19 | B23: Mario Kambani | C23: General Works | D23: 21 | E23: 2 | F23: =D23+E23 -> 23 | H23: =F23-G23 -> 23
A24: 20 | B24: Chanda Chileshe | C24: Primary Teacher | D24: 4 | E24: 2 | F24: =D24+E24 -> 6 | H24: =F24-G24 -> 6
A25: 21 | B25: Timothy Phiri | C25: General Works | D25: 26 | E25: 2 | F25: =D25+E25 -> 28 | H25: =F25-G25 -> 28
A26: 22 | B26: Winnie Sishwani | C26: Teacher Secondary | D26: 5 | E26: 2 | F26: =D26+E26 -> 7 | H26: =F26-G26 -> 7
A27: 23 | B27: Valentine Zulu | C27: Teacher Secondary | D27: 2 | E27: 2 | F27: =D27+E27 -> 4 | H27: =F27-G27 -> 4
A28: 24 | B28: Tembo Diana | C28: lib Assitant | D28: 18 | E28: 2 | F28: =D28+E28 -> 20 | H28: =F28-G28 -> 20
A29: 25 | D29: 6 | E29: 2 | F29: =D29+E29 -> 8 | H29: =F29-G29 -> 8
A30: 26 | B30: Anderson Ngulube | C30: Secondary | D30: 2 | E30: 2 | F30: =D30+E30 -> 4 | H30: =F30-G30 -> 4
A31: 27 | D31: 6 | E31: 2 | F31: =D31+E31 -> 8 | H31: =F31-G31 -> 8
A32: 28 | B32: kalongana Nyambe | C32: security | D32: 94 | E32: 2 | F32: =D32+E32 -> 96 | G32: 1 | H32: =F32-G32 -> 95
A33: 29 | B33: Namakala Mackenzie | C33: Primary Head | D33: 22 | E33: 2 | F33: =D33+E33 -> 24 | H33: =F33-G33 -> 24
A34: 30 | B34: Mashewa Alice | C34: Primary | D34: 2 | E34: 2 | F34: =D34+E34 -> 4 | H34: =F34-G34 -> 4
A35: 31 | B35: Rose Daka | C35: PCELC | D35: 2 | E35: 2 | F35: =D35+E35 -> 4 | H35: =F35-G35 -> 4
A36: 32 | B36: priscilla Muluso | C36: primary | D36: 2 | E36: 2 | F36: =D36+E36 -> 4 | H36: =F36-G36 -> 4
A37: 33 | B37: Banda Esther | C37: prmary | D37: 2 | E37: 2 | F37: =D37+E37 -> 4 | G37: 14 | H37: =F37-G37 -> -10
A38: 34 | B38: beatrice Kasuka | C38: General works | D38: 54 | E38: 2 | F38: =D38+E38 -> 56 | H38: =F38-G38 -> 56
A39: 35 | B39: gwaba Mweemba | C39: Head Secondary | D39: 40 | E39: 2 | F39: =D39+E39 -> 42 | H39: =F39-G39 -> 42
A40: 36 | B40: caleb Simuchimba | C40: Secondary | D40: 2 | E40: 2 | F40: =D40+E40 -> 4 | H40: =F40-G40 -> 4
A41: 37 | B41: Kabemba Kim Kabemba | C41: Primary | D41: 2 | E41: 2 | F41: =D41+E41 -> 4 | G41: 4 | H41: =F41-G41 -> 0
...

Sheet Jul-25
C2: CHUDLEIGH HOUSE SCHOOL STAFF LEAVE DAYS
C3: FOR THE MONTH OF FEBRUARY 2022
B4: NAME | C4: POSITION | D4: OPENING | E4: DAYS EARNED | F4: TOTAL | G4: DAYS TAKEN | H4: NET
A5: 1 | B5: ABBY PHIRI | C5: Financial Controller | D5: 31 | E5: 2 | F5: =D5+E5 -> 33 | H5: =F5-G5 -> 33
A6: 2 | B6: Margaret Mukondwa | C6: Executive Assistant | D6: 132 | E6: 2 | F6: =D6+E6 -> 134 | H6: =F6-G6 -> 134
A7: 3 | B7: mizzie Mutambo | C7: ass. Accountant | D7: 48 | E7: 2 | F7: =D7+E7 -> 50 | H7: =F7-G7 -> 50
A8: 4 | B8: Tembo Bertha | C8: teacher Primary | D8: 3 | E8: 2 | F8: =D8+E8 -> 5 | H8: =F8-G8 -> 5
A9: 5 | B9: Kamanugu Mriiam | C9: Teacher Primary | D9: 4 | E9: 2 | F9: =D9+E9 -> 6 | H9: =F9-G9 -> 6
A10: 6 | B10: Chisenga Gillian Mwambela | C10: teacher Primary | D10: 4 | E10: 2 | F10: =D10+E10 -> 6 | H10: =F10-G10 -> 6
A11: 7 | B11: Nambela Mercy | C11: teacher Primary | D11: 4 | E11: 2 | F11: =D11+E11 -> 6 | H11: =F11-G11 -> 6
A12: 8 | B12: Nakache Chewe | C12: Teacher Primary | D12: 4 | E12: 2 | F12: =D12+E12 -> 6 | H12: =F12-G12 -> 6
A13: 9 | B13: Zimba Francisca | C13: teacher Primary | D13: 4 | E13: 2 | F13: =D13+E13 -> 6 | H13: =F13-G13 -> 6
A14: 10 | B14: Ireen Nachinga | C14: teacher Primary | D14: 4 | E14: 2 | F14: =D14+E14 -> 6 | H14: =F14-G14 -> 6
A15: 11 | B15: Munyati Senitor | C15: PCELC - Teacher | D15: 3 | E15: 2 | F15: =D15+E15 -> 5 | H15: =F15-G15 -> 5
A16: 12 | B16: Banda Mary | C16: PCELC- Teacher | D16: 12 | E16: 2 | F16: =D16+E16 -> 14 | H16: =F16-G16 -> 14
... A28: 24 | B28: Tembo Diana | C28: lib Assitant | D28: 20 | E28: 2 | F28: =D28+E28 -> 22 | H28: =F28-G28 -> 22
A29: 25 | D29: 8 | E29: 2 | F29: =D29+E29 -> 10 | H29: =F29-G29 -> 10
A30: 26 | B30: Anderson Ngulube | C30: Secondary | D30: 4 | E30: 2 | F30: =D30+E30 -> 6 | H30: =F30-G30 -> 6
A31: 27 | D31: 8 | E31: 2 | F31: =D31+E31 -> 10 | H31: =F31-G31 -> 10
A32: 28 | B32: kalongana Nyambe | C32: security | D32: 95 | E32: 2 | F32: =D32+E32 -> 97 | H32: =F32-G32 -> 97
A33: 29 | B33: Namakala Mackenzie | C33: Primary Head | D33: 24 | E33: 2 | F33: =D33+E33 -> 26 | H33: =F33-G33 -> 26
A34: 30 | B34: Mashewa Alice | C34: Primary | D34: 4 | E34: 2 | F34: =D34+E34 -> 6 | H34: =F34-G34 -> 6
A35: 31 | B35: Rose Daka | C35: PCELC | D35: 4 | E35: 2 | F35: =D35+E35 -> 6 | H35: =F35-G35 -> 6
A36: 32 | B36: priscilla Muluso | C36: primary | D36: 4 | E36: 2 | F36: =D36+E36 -> 6 | H36: =F36-G36 -> 6
A37: 33 | B37: Banda Esther | C37: prmary | D37: -10 | E37: 2 | F37: =D37+E37 -> -8 | H37: =F37-G37 -> -8
A38: 34 | B38: beatrice Kasuka | C38: General works | D38: 56 | E38: 2 | F38: =D38+E38 -> 58 | H38: =F38-G38 -> 58
A39: 35 | B39: gwaba Mweemba | C39: Head Secondary | D39: 42 | E39: 2 | F39: =D39+E39 -> 44 | H39: =F39-G39 -> 44
A40: 36 | B40: caleb Simuchimba | C40: Secondary | D40: 4 | E40: 2 | F40: =D40+E40 -> 6 | H40: =F40-G40 -> 6
A41: 37 | B41: Kabemba Kim Kabemba | C41: Primary | D41: 0 | E41: 2 | F41: =D41+E41 -> 2 | H41: =F41-G41 -> 2
A42: 38 | B42: mtonga camila | C42: Primary | D42: 4 | E42: 2 | F42: =D42+E42 -> 6 | H42: =F42-G42 -> 6
A43: 39 | B43: Kasaro Flatter | C43: Primary - senior | D43: 5 | E43: 2 | F43: =D43+E43 -> 7 | H43: =F43-G43 -> 7
... A74: 70 | B74: Lungu Stella | C74: General Works | D74: 49 | E74: 2 | F74: =D74+E74 -> 51 | H74: =F74-G74 -> 51
A75: 71 | D75: -2 | E75: 2 | F75: =D75+E75 -> 0 | H75: =F75-G75 -> 0
A76: 72 | B76: harriet Tembo | C76: PCELC | D76: 68 | E76: 2 | F76: =D76+E76 -> 70 | H76: =F76-G76 -> 70
A77: 73 | B77: imbuwa Kakanda | C77: PCEL | D77: 50 | E77: 2 | F77: =D77+E77 -> 52 | H77: =F77-G77 -> 52
A78: 74 | B78: situmbeko mwangala | C78: elc helper | D78: 54 | E78: 2 | F78: =D78+E78 -> 56 | H78: =F78-G78 -> 56
A79: 75 | B79: Esnart Mwanza | C79: PCELC | D79: 36 | E79: 2 | F79: =D79+E79 -> 38 | H79: =F79-G79 -> 38
A80: 76 | B80: nakaundi getrude | C80: elc helper | D80: 77 | E80: 2 | F80: =D80+E80 -> 79 | H80: =F80-G80 -> 79
A81: 77 | B81: njovu samson | C81: driver | D81: 92 | E81: 2 | F81: =D81+E81 -> 94 | H81: =F81-G81 -> 94
A82: 78 | B82: nicholus nsemiwe | C82: ass accountant | D82: 208 | E82: 2 | F82: =D82+E82 -> 210 | H82: =F82-G82 -> 210
...

Sheet Aug-25
C2: CHUDLEIGH HOUSE SCHOOL STAFF LEAVE DAYS
C3: FOR THE MONTH OF FEBRUARY 2022
B4: NAME | C4: POSITION | D4: OPENING | E4: DAYS EARNED | F4: TOTAL | G4: DAYS TAKEN | H4: NET
A5: 1 | B5: ABBY PHIRI | C5: Financial Controller | D5: 33 | E5: 2 | F5: =D5+E5 -> 35 | H5: =F5-G5 -> 35
A6: 2 | B6: Margaret Mukondwa | C6: Executive Assistant | D6: 134 | E6: 2 | F6: =D6+E6 -> 136 | H6: =F6-G6 -> 136
A7: 3 | B7: mizzie Mutambo | C7: ass. Accountant | D7: 50 | E7: 2 | F7: =D7+E7 -> 52 | G7: 2 | H7: =F7-G7 -> 50
A8: 4 | B8: Tembo Bertha | C8: teacher Primary | D8: 5 | E8: 2 | F8: =D8+E8 -> 7 | G8: 10 | H8: =F8-G8 -> -3
A9: 5 | B9: Kamanugu Mriiam | C9: Teacher Primary | D9: 6 | E9: 2 | F9: =D9+E9 -> 8 | H9: =F9-G9 -> 8
A10: 6 | B10: Chisenga Gillian Mwambela | C10: teacher Primary | D10: 6 | E10: 2 | F10: =D10+E10 -> 8 | G10: 10 | H10: =F10-G10 -> -2
A11: 7 | B11: Nambela Mercy | C11: teacher Primary | D11: 6 | E11: 2 | F11: =D11+E11 -> 8 | G11: 10 | H11: =F11-G11 -> -2
A12: 8 | B12: Nakache Chewe | C12: Teacher Primary | D12: 6 | E12: 2 | F12: =D12+E12 -> 8 | G12: 10 | H12: =F12-G12 -> -2
A13: 9 | B13: Zimba Francisca | C13: teacher Primary | D13: 6 | E13: 2 | F13: =D13+E13 -> 8 | G13: 10 | H13: =F13-G13 -> -2
A14: 10 | B14: Ireen Nachinga | C14: teacher Primary | D14: 6 | E14: 2 | F14: =D14+E14 -> 8 | G14: 10 | H14: =F14-G14 -> -2
A15: 11 | B15: Munyati Senitor | C15: PCELC - Teacher | D15: 5 | E15: 2 | F15: =D15+E15 -> 7 | G15: 10 | H15: =F15-G15 -> -3
A16: 12 | B16: Banda Mary | C16: PCELC- Teacher | D16: 14 | E16: 2 | F16: =D16+E16 -> 16 | G16: 10 | H16: =F16-G16 -> 6
A17: 13 | B17: Mwanida Jere | C17: PCELC- Teacher | D17: 6 | E17: 2 | F17: =D17+E17 -> 8 | G17: 10 | H17: =F17-G17 -> -2
A18: 14 | B18: George Kakoma | C18: Cashier | D18: 29 | E18: 2 | F18: =D18+E18 -> 31 | H18: =F18-G18 -> 31
A19: 15 | B19: Masebo Hudson | C19: School Bursar | D19: 105 | E19: 2 | F19: =D19+E19 -> 107 | H19: =F19-G19 -> 107
A20: 16 | B20: Nancy nanyangwe | C20: Cashier | D20: 79 | E20: 2 | F20: =D20+E20 -> 81 | H20: =F20-G20 -> 81
A21: 17 | B21: samuel Chinyama | C21: Teacher | D21: 8 | E21: 2 | F21: =D21+E21 -> 10 | G21: 5 | H21: =F21-G21 -> 5
A22: 18 | B22: besa Godfrey | C22: Senior Techer | D22: 7 | E22: 2 | F22: =D22+E22 -> 9 | G22: 5 | H22: =F22-G22 -> 4
A23: 19 | B23: Mario Kambani | C23: General Works | D23: 25 | E23: 2 | F23: =D23+E23 -> 27 | H23: =F23-G23 -> 27
A24: 20 | B24: Chanda Chileshe | C24: Primary Teacher | D24: 8 | E24: 2 | F24: =D24+E24 -> 10 | G24: 10 | H24: =F24-G24 -> 0
A25: 21 | B25: Timothy Phiri | C25: General Works | D25: 30 | E25: 2 | F25: =D25+E25 -> 32 | G25: 6 | H25: =F25-G25 -> 26
A26: 22 | B26: Winnie Sishwani | C26: Teacher Secondary | D26: 9 | E26: 2 | F26: =D26+E26 -> 11 | G26: 5 | H26: =F26-G26 -> 6
A27: 23 | B27: Valentine Zulu | C27: Teacher Secondary | D27: 6 | E27: 2 | F27: =D27+E27 -> 8 | G27: 5 | H27: =F27-G27 -> 3
A28: 24 | B28: Tembo Diana | C28: lib Assitant | D28: 22 | E28: 2 | F28: =D28+E28 -> 24 | G28: 10 | H28: =F28-G28 -> 14
A29: 25 | B29: Moses Daka | C29: Security | D29: 115 | E29: 2 | F29: =D29+E29 -> 117 | H29: =F29-G29 -> 117
A30: 26 | B30: Anderson Ngulube | C30: Secondary | D30: 6 | E30: 2 | F30: =D30+E30 -> 8 | G30: 5 | H30: =F30-G30 -> 3
A31: 27 | B31: Mbangweta Mbagweta | C31: Primary | D31: 6 | E31: 2 | F31: =D31+E31 -> 8 | G31: 10 | H31: =F31-G31 -> -2
A32: 28 | B32: kalongana Nyambe | C32: security | D32: 97 | E32: 2 | F32: =D32+E32 -> 99 | H32: =F32-G32 -> 99
A33: 29 | B33: Namakala Mackenzie | C33: Primary Head | D33: 26 | E33: 2 | F33: =D33+E33 -> 28 | G33: 6 | H33: =F33-G33 -> 22
A34: 30 | B34: Mashewa Alice | C34: Primary | D34: 6 | E34: 2 | F34: =D34+E34 -> 8 | G34: 10 | H34: =F34-G34 -> -2
A35: 31 | B35: Rose Daka | C35: PCELC | D35: 6 | E35: 2 | F35: =D35+E35 -> 8 | G35: 10 | H35: =F35-G35 -> -2
A36: 32 | B36: priscilla Muluso | C36: primary | D36: 6 | E36: 2 | F36: =D36+E36 -> 8 | G36: 10 | H36: =F36-G36 -> -2
A37: 33 | B37: Banda Esther | C37: prmary | D37: -8 | E37: 2 | F37: =D37+E37 -> -6 | H37: =F37-G37 -> -6
A38: 34 | B38: beatrice Kasuka | C38: General works | D38: 58 | E38: 2 | F38: =D38+E38 -> 60 | H38: =F38-G38 -> 60
A39: 35 | B39: gwaba Mweemba | C39: Head Secondary | D39: 44 | E39: 2 | F39: =D39+E39 -> 46 | G39: 5 | H39: =F39-G39 -> 41
A40: 36 | B40: caleb Simuchimba | C40: Secondary | D40: 6 | E40: 2 | F40: =D40+E40 -> 8 | G40: 5 | H40: =F40-G40 -> 3
A41: 37 | B41: Kabemba Kim Kabemba | C41: Primary | D41: 2 | E41: 2 | F41: =D41+E41 -> 4 | G41: 10 | H41: =F41-G41 -> -6
...

Sheet Sep-25
C2: CHUDLEIGH HOUSE SCHOOL STAFF LEAVE DAYS
C3: FOR THE MONTH OF FEBRUARY 2022
B4: NAME | C4: POSITION | D4: OPENING | E4: DAYS EARNED | F4: TOTAL | G4: DAYS TAKEN | H4: NET
A5: 1 | B5: ABBY PHIRI | C5: Financial Controller | D5: 35 | E5: 2 | F5: =D5+E5 -> 37 | H5: =F5-G5 -> 37
A6: 2 | B6: Margaret Mukondwa | C6: Executive Assistant | D6: 136 | E6: 2 | F6: =D6+E6 -> 138 | H6: =F6-G6 -> 138
A7: 3 | B7: mizzie Mutambo | C7: ass. Accountant | D7: 50 | E7: 2 | F7: =D7+E7 -> 52 | H7: =F7-G7 -> 52
A8: 4 | B8: Tembo Bertha | C8: teacher Primary | D8: -3 | E8: 2 | F8: =D8+E8 -> -1 | H8: =F8-G8 -> -1
A9: 5 | B9: Kamanugu Mriiam | C9: Teacher Primary | D9: 8 | E9: 2 | F9: =D9+E9 -> 10 | H9: =F9-G9 -> 10
A10: 6 | B10: Chisenga Gillian Mwambela | C10: teacher Primary | D10: -2 | E10: 2 | F10: =D10+E10 -> 0 | H10: =F10-G10 -> 0
A11: 7 | B11: Nambela Mercy | C11: teacher Primary | D11: -2 | E11: 2 | F11: =D11+E11 -> 0 | G11: 2 | H11: =F11-G11 -> -2
A12: 8 | B12: Nakache Chewe | C12: Teacher Primary | D12: -2 | E12: 2 | F12: =D12+E12 -> 0 | H12: =F12-G12 -> 0
A13: 9 | B13: Zimba Francisca | C13: teacher Primary | D13: -2 | E13: 2 | F13: =D13+E13 -> 0 | H13: =F13-G13 -> 0
A14: 10 | B14: Ireen Nachinga | C14: teacher Primary | D14: -2 | E14: 2 | F14: =D14+E14 -> 0 | H14: =F14-G14 -> 0
A15: 11 | B15: Munyati Senitor | C15: PCELC - Teacher | D15: -3 | E15: 2 | F15: =D15+E15 -> -1 | H15: =F15-G15 -> -1
A16: 12 | B16: Banda Mary | C16: PCELC- Teacher | D16: 6 | E16: 2 | F16: =D16+E16 -> 8 | H16: =F16-G16 -> 8
A17: 13 | B17: Mwanida Jere | C17: PCELC- Teacher | D17: -2 | E17: 2 | F17: =D17+E17 -> 0 | H17: =F17-G17 -> 0
A18: 14 | B18: George Kakoma | C18: Cashier | D18: 31 | E18: 2 | F18: =D18+E18 -> 33 | H18: =F18-G18 -> 33
A19: 15 | B19: Masebo Hudson | C19: School Bursar | D19: 107 | E19: 2 | F19: =D19+E19 -> 109 | H19: =F19-G19 -> 109
A20: 16 | B20: Nancy nanyangwe | C20: Cashier | D20: 81 | E20: 2 | F20: =D20+E20 -> 83 | G20: 1 | H20: =F20-G20 -> 82
A21: 17 | B21: samuel Chinyama | C21: Teacher | D21: 5 | E21: 2 | F21: =D21+E21 -> 7 | H21: =F21-G21 -> 7
A22: 18 | B22: besa Godfrey | C22: Senior Techer | D22: 4 | E22: 2 | F22: =D22+E22 -> 6 | H22: =F22-G22 -> 6
A23: 19 | B23: Esau Chinkalata | C23: Teacher Secondary | D23: 0 | E23: 2 | F23: =D23+E23 -> 2 | H23: =F23-G23 -> 2
A24: 20 | B24: Chanda Chileshe | C24: Primary Teacher | D24: 0 | E24: 2 | F24: =D24+E24 -> 2 | H24: =F24-G24 -> 2
A25: 21 | B25: Timothy Phiri | C25: General Works | D25: 26 | E25: 2 | F25: =D25+E25 -> 28 | H25: =F25-G25 -> 28
A26: 22 | B26: Winnie Sishwani | C26: Teacher Secondary | D26: 6 | E26: 2 | F26: =D26+E26 -> 8 | H26: =F26-G26 -> 8
A27: 23 | B27: Valentine Zulu | C27: Teacher Secondary | D27: 3 | E27: 2 | F27: =D27+E27 -> 5 | H27: =F27-G27 -> 5
A28: 24 | B28: Tembo Diana | C28: lib Assitant | D28: 14 | E28: 2 | F28: =D28+E28 -> 16 | H28: =F28-G28 -> 16
A29: 25 | B29: Moses Daka | C29: Security | D29: 117 | E29: 2 | F29: =D29+E29 -> 119 | H29: =F29-G29 -> 119
A30: 26 | B30: Anderson Ngulube | C30: Secondary | D30: 3 | E30: 2 | F30: =D30+E30 -> 5 | H30: =F30-G30 -> 5
A31: 27 | B31: Mbangweta Mbagweta | C31: Primary | D31: -2 | E31: 2 | F31: =D31+E31 -> 0 | H31: =F31-G31 -> 0
A32: 28 | B32: kalongana Nyambe | C32: security | D32: 99 | E32: 2 | F32: =D32+E32 -> 101 | G32: 1 | H32: =F32-G32 -> 100
A33: 29 | B33: Namakala Mackenzie | C33: Primary Head | D33: 22 | E33: 2 | F33: =D33+E33 -> 24 | H33: =F33-G33 -> 24
A34: 30 | B34: Mashewa Alice | C34: Primary | D34: -2 | E34: 2 | F34: =D34+E34 -> 0 | H34: =F34-G34 -> 0
A35: 31 | B35: Rose Daka | C35: PCELC | D35: -2 | E35: 2 | F35: =D35+E35 -> 0 | H35: =F35-G35 -> 0
A36: 32 | B36: priscilla Muluso | C36: primary | D36: -2 | E36: 2 | F36: =D36+E36 -> 0 | H36: =F36-G36 -> 0
A37: 33 | B37: Banda Esther | C37: prmary | D37: -6 | E37: 2 | F37: =D37+E37 -> -4 | H37: =F37-G37 -> -4
A38: 34 | B38: beatrice Kasuka | C38: General works | D38: 60 | E38: 2 | F38: =D38+E38 -> 62 | H38: =F38-G38 -> 62
A39: 35 | B39: gwaba Mweemba | C39: Head Secondary | D39: 41 | E39: 2 | F39: =D39+E39 -> 43 | H39: =F39-G39 -> 43
A40: 36 | B40: caleb Simuchimba | C40: Secondary | D40: 3 | E40: 2 | F40: =D40+E40 -> 5 | H40: =F40-G40 -> 5
A41: 37 | B41: Kabemba Kim Kabemba | C41: Primary | D41: -6 | E41: 2 | F41: =D41+E41 -> -4 | H41: =F41-G41 -> -4
...

Sheet Oct-25
C2: CHUDLEIGH HOUSE SCHOOL STAFF LEAVE DAYS
C3: FOR THE MONTH OF FEBRUARY 2022
B4: NAME | C4: POSITION | D4: OPENING | E4: DAYS EARNED | F4: TOTAL | G4: DAYS TAKEN | H4: NET
A5: 1 | B5: ABBY PHIRI | C5: Financial Controller | D5: 37 | E5: 2 | F5: =D5+E5 -> 39 | H5: =F5-G5 -> 39
A6: 2 | B6: Margaret Mukondwa | C6: Executive Assistant | D6: 138 | E6: 2 | F6: =D6+E6 -> 140 | G6: 4 | H6: =F6-G6 -> 136
A7: 3 | B7: mizzie Mutambo | C7: ass. Accountant | D7: 52 | E7: 2 | F7: =D7+E7 -> 54 | H7: =F7-G7 -> 54
A8: 4 | B8: Tembo Bertha | C8: teacher Primary | D8: -1 | E8: 2 | F8: =D8+E8 -> 1 | H8: =F8-G8 -> 1
A9: 5 | B9: Kamanugu Mriiam | C9: Teacher Primary | D9: 10 | E9: 2 | F9: =D9+E9 -> 12 | H9: =F9-G9 -> 12
A10: 6 | B10: Chisenga Gillian Mwambela | C10: teacher Primary | D10: 0 | E10: 2 | F10: =D10+E10 -> 2 | H10: =F10-G10 -> 2
A11: 7 | B11: Nambela Mercy | C11: teacher Primary | D11: -2 | E11: 2 | F11: =D11+E11 -> 0 | H11: =F11-G11 -> 0
A12: 8 | B12: Nakache Chewe | C12: Teacher Primary | D12: 0 | E12: 2 | F12: =D12+E12 -> 2 | H12: =F12-G12 -> 2
A13: 9 | B13: Zimba Francisca | C13: teacher Primary | D13: 0 | E13: 2 | F13: =D13+E13 -> 2 | H13: =F13-G13 -> 2
A14: 10 | B14: Ireen Nachinga | C14: teacher Primary | D14: 0 | E14: 2 | F14: =D14+E14 -> 2 | H14: =F14-G14 -> 2
A15: 11 | B15: Munyati Senitor | C15: PCELC - Teacher | D15: -1 | E15: 2 | F15: =D15+E15 -> 1 | H15: =F15-G15 -> 1
A16: 12 | B16: Banda Mary | C16: PCELC- Teacher | D16: 8 | E16: 2 | F16: =D16+E16 -> 10 | H16: =F16-G16 -> 10
A17: 13 | B17: Mwanida Jere | C17: PCELC- Teacher | D17: 0 | E17: 2 | F17: =D17+E17 -> 2 | G17: 2 | H17: =F17-G17 -> 0
A18: 14 | B18: George Kakoma | C18: Cashier | D18: 33 | E18: 2 | F18: =D18+E18 -> 35 | H18: =F18-G18 -> 35
A19: 15 | B19: Masebo Hudson | C19: School Bursar | D19: 109 | E19: 2 | F19: =D19+E19 -> 111 | H19: =F19-G19 -> 111
A20: 16 | B20: Nancy nanyangwe | C20: Cashier | D20: 82 | E20: 2 | F20: =D20+E20 -> 84 | G20: 2 | H20: =F20-G20 -> 82
A21: 17 | B21: samuel Chinyama | C21: Teacher | D21: 7 | E21: 2 | F21: =D21+E21 -> 9 | H21: =F21-G21 -> 9
A22: 18 | B22: besa Godfrey | C22: Senior Techer | D22: 6 | E22: 2 | F22: =D22+E22 -> 8 | H22: =F22-G22 -> 8
A23: 19 | B23: Esau Chinkalata | C23: Teacher Secondary | D23: 2 | E23: 2 | F23: =D23+E23 -> 4 | H23: =F23-G23 -> 4
A24: 20 | B24: Chanda Chileshe | C24: Primary Teacher | D24: 2 | E24: 2 | F24: =D24+E24 -> 4 | H24: =F24-G24 -> 4
A25: 21 | B25: Timothy Phiri | C25: General Works | D25: 28 | E25: 2 | F25: =D25+E25 -> 30 | H25: =F25-G25 -> 30
A26: 22 | B26: Winnie Sishwani | C26: Teacher Secondary | D26: 8 | E26: 2 | F26: =D26+E26 -> 10 | H26: =F26-G26 -> 10
A27: 23 | B27: Valentine Zulu | C27: Teacher Secondary | D27: 5 | E27: 2 | F27: =D27+E27 -> 7 | H27: =F27-G27 -> 7
A28: 24 | B28: Tembo Diana | C28: lib Assitant | D28: 16 | E28: 2 | F28: =D28+E28 -> 18 | H28: =F28-G28 -> 18
A29: 25 | B29: Moses Daka | C29: Security | D29: 119 | E29: 2 | F29: =D29+E29 -> 121 | G29: 33 | H29: =F29-G29 -> 88
A30: 26 | B30: Anderson Ngulube | C30: Secondary | D30: 5 | E30: 2 | F30: =D30+E30 -> 7 | H30: =F30-G30 -> 7
A31: 27 | B31: Mbangweta Mbagweta | C31: Primary | D31: 0 | E31: 2 | F31: =D31+E31 -> 2 | H31: =F31-G31 -> 2
A32: 28 | B32: kalongana Nyambe | C32: security | D32: 100 | E32: 2 | F32: =D32+E32 -> 102 | H32: =F32-G32 -> 102
A33: 29 | B33: Namakala Mackenzie | C33: Primary Head | D33: 24 | E33: 2 | F33: =D33+E33 -> 26 | G33: 2 | H33: =F33-G33 -> 24
A34: 30 | B34: Mashewa Alice | C34: Primary | D34: 0 | E34: 2 | F34: =D34+E34 -> 2 | H34: =F34-G34 -> 2
A35: 31 | B35: Rose Daka | C35: PCELC | D35: 0 | E35: 2 | F35: =D35+E35 -> 2 | H35: =F35-G35 -> 2
A36: 32 | B36: priscilla Muluso | C36: primary | D36: 0 | E36: 2 | F36: =D36+E36 -> 2 | G36: 3 | H36: =F36-G36 -> -1
A37: 33 | B37: Banda Esther | C37: prmary | D37: -4 | E37: 2 | F37: =D37+E37 -> -2 | H37: =F37-G37 -> -2
A38: 34 | B38: beatrice Kasuka | C38: General works | D38: 62 | E38: 2 | F38: =D38+E38 -> 64 | H38: =F38-G38 -> 64
A39: 35 | B39: gwaba Mweemba | C39: Head Secondary | D39: 43 | E39: 2 | F39: =D39+E39 -> 45 | H39: =F39-G39 -> 45
A40: 36 | B40: caleb Simuchimba | C40: Secondary | D40: 5 | E40: 2 | F40: =D40+E40 -> 7 | H40: =F40-G40 -> 7
A41: 37 | B41: Kabemba Kim Kabemba | C41: Primary | D41: -4 | E41: 2 | F41: =D41+E41 -> -2 | G41: 4 | H41: =F41-G41 -> -6
...

Sheet Nov-25
C2: CHUDLEIGH HOUSE SCHOOL STAFF LEAVE DAYS
C3: FOR THE MONTH OF FEBRUARY 2022
B4: NAME | C4: POSITION | D4: OPENING | E4: DAYS EARNED | F4: TOTAL | G4: DAYS TAKEN | H4: NET
A5: 1 | B5: ABBY PHIRI | D5: ='Oct-25'!H5 -> 39 | E5: 2 | F5: =D5+E5 -> 41 | H5: =F5-G5 -> 41
A6: 2 | B6: Margaret Mukondwa | C6: Executive Assistant | D6: ='Oct-25'!H6 -> 136 | E6: 2 | F6: =D6+E6 -> 138 | H6: =F6-G6 -> 138
A7: 3 | B7: mizzie Mutambo | C7: ass. Accountant | D7: ='Oct-25'!H7 -> 54 | E7: 2 | F7: =D7+E7 -> 56 | H7: =F7-G7 -> 56
A8: 4 | B8: Tembo Bertha | C8: teacher Primary | D8: ='Oct-25'!H8 -> 1 | E8: 2 | F8: =D8+E8 -> 3 | H8: =F8-G8 -> 3
A9: 5 | B9: Kamanugu Mriiam | C9: Teacher Primary | D9: ='Oct-25'!H9 -> 12 | E9: 2 | F9: =D9+E9 -> 14 | H9: =F9-G9 -> 14
A10: 6 | B10: Chisenga Gillian Mwambela | C10: teacher Primary | D10: ='Oct-25'!H10 -> 2 | E10: 2 | F10: =D10+E10 -> 4 | H10: =F10-G10 -> 4
A11: 7 | B11: Nambela Mercy | C11: teacher Primary | D11: ='Oct-25'!H11 -> 0 | E11: 2 | F11: =D11+E11 -> 2 | H11: =F11-G11 -> 2
A12: 8 | B12: Mutale Mirram | C12: teacher Primary | D12: ='Oct-25'!H12 -> 2 | E12: 2 | F12: =D12+E12 -> 4 | H12: =F12-G12 -> 4
A13: 9 | B13: Zimba Francisca | C13: teacher Primary | D13: ='Oct-25'!H13 -> 2 | E13: 9 | F13: =D13+E13 -> 11 | H13: =F13-G13 -> 11
A14: 10 | B14: Ireen Nachinga | C14: teacher Primary | D14: ='Oct-25'!H14 -> 2 | E14: 2 | F14: =D14+E14 -> 4 | H14: =F14-G14 -> 4
A15: 11 | B15: Munyati Senitor | C15: PCELC - Teacher | D15: ='Oct-25'!H15 -> 1 | E15: 2 | F15: =D15+E15 -> 3 | H15: =F15-G15 -> 3
A16: 12 | B16: Banda Mary | C16: PCELC- Teacher | D16: ='Oct-25'!H16 -> 10 | E16: 2 | F16: =D16+E16 -> 12 | G16: 3 | H16: =F16-G16 -> 9
A17: 13 | B17: Mwanida Jere | C17: PCELC- Teacher | D17: ='Oct-25'!H17 -> 0 | E17: 2 | F17: =D17+E17 -> 2 | H17: =F17-G17 -> 2
A18: 14 | B18: George Kakoma | C18: Cashier | D18: ='Oct-25'!H18 -> 35 | E18: 2 | F18: =D18+E18 -> 37 | H18: =F18-G18 -> 37
A19: 15 | B19: Masebo Hudson | C19: School Bursar | D19: ='Oct-25'!H19 -> 111 | E19: 2 | F19: =D19+E19 -> 113 | H19: =F19-G19 -> 113
A20: 16 | B20: Nancy nanyangwe | C20: Cashier | D20: ='Oct-25'!H20 -> 82 | E20: 2 | F20: =D20+E20 -> 84 | H20: =F20-G20 -> 84
A21: 17 | B21: samuel Chinyama | C21: Teacher | D21: ='Oct-25'!H21 -> 9 | E21: 2 | F21: =D21+E21 -> 11 | H21: =F21-G21 -> 11
A22: 18 | B22: besa Godfrey | C22: Senior Techer | D22: ='Oct-25'!H22 -> 8 | E22: 2 | F22: =D22+E22 -> 10 | H22: =F22-G22 -> 10
A23: 19 | B23: Mario Kambani | C23: General Works | D23: ='Oct-25'!H23 -> 4 | E23: 2 | F23: =D23+E23 -> 6 | H23: =F23-G23 -> 6
A24: 20 | B24: Josaya Milanzi | C24: Teacher | D24: ='Oct-25'!H24 -> 4 | E24: 2 | F24: =D24+E24 -> 6 | H24: =F24-G24 -> 6
A25: 21 | B25: Timothy Phiri | C25: General Works | D25: ='Oct-25'!H25 -> 30 | E25: 2 | F25: =D25+E25 -> 32 | H25: =F25-G25 -> 32
A26: 22 | B26: Winnie Sishwani | C26: Teacher Secondary | D26: ='Oct-25'!H26 -> 10 | E26: 2 | F26: =D26+E26 -> 12 | H26: =F26-G26 -> 12
A27: 23 | B27: Valentine Zulu | C27: Teacher Secondary | D27: ='Oct-25'!H27 -> 7 | E27: 2 | F27: =D27+E27 -> 9 | H27: =F27-G27 -> 9
A28: 24 | B28: Tembo Diana | C28: lib Assitant | D28: ='Oct-25'!H28 -> 18 | E28: 2 | F28: =D28+E28 -> 20 | H28: =F28-G28 -> 20
... A40: 36 | B40: caleb Simuchimba | C40: Secondary | D40: ='Oct-25'!H40 -> 7 | E40: 2 | F40: =D40+E40 -> 9 | H40: =F40-G40 -> 9
A41: 37 | B41: Kabemba Kim Kabemba | C41: Primary | D41: ='Oct-25'!H41 -> -6 | E41: 2 | F41: =D41+E41 -> -4 | G41: 8 | H41: =F41-G41 -> -12
A42: 38 | B42: mtonga camila | C42: Primary | D42: ='Oct-25'!H42 -> -2 | E42: 2 | F42: =D42+E42 -> 0 | H42: =F42-G42 -> 0
A43: 39 | B43: Kasaro Flatter | C43: Primary - senior | D43: ='Oct-25'!H43 -> 8 | E43: 2 | F43: =D43+E43 -> 10 | H43: =F43-G43 -> 10
A44: 40 | B44: Jere Davison | C44: Primary | D44: ='Oct-25'!H44 -> 3 | E44: 0 | F44: =D44+E44 -> 3 | H44: =F44-G44 -> 3
A45: 41 | B45: Gideon Chikumba | C45: teacher Primary | D45: ='Oct-25'!H45 -> 0 | E45: 0 | F45: =D45+E45 -> 0 | H45: =F45-G45 -> 0
A46: 42 | B46: Khondowe Laureen | C46: Primary | D46: ='Oct-25'!H46 -> 2 | E46: 0 | F46: =D46+E46 -> 2 | H46: =F46-G46 -> 2
A47: 43 | B47: mvula Sayenera | C47: Secondary | D47: ='Oct-25'!H47 -> 7 | E47: 0 | F47: =D47+E47 -> 7 | H47: =F47-G47 -> 7
A48: 44 | B48: Faith Hanunga | C48: Secretary | D48: ='Oct-25'!H48 -> 12 | E48: 2 | F48: =D48+E48 -> 14 | H48: =F48-G48 -> 14
A49: 45 | B49: Chinuuka Gloria | C49: Secretary | D49: ='Oct-25'!H49 -> 100 | E49: 2 | F49: =D49+E49 -> 102 | H49: =F49-G49 -> 102
A50: 46 | B50: Arthur Nyangu | C50: Secondary - assistant | D50: ='Oct-25'!H50 -> 55 | E50: 0 | F50: =D50+E50 -> 55 | H50: =F50-G50 -> 55
A51: 47 | B51: robert Shikupa | C51: PCELC assistant | D51: ='Oct-25'!H51 -> 85 | E51: 2 | F51: =D51+E51 -> 87 | H51: =F51-G51 -> 87
A52: 48 | B52: Hellen Mbewe | C52: Head PCELC | D52: ='Oct-25'!H52 -> 124 | E52: 2 | F52: =D52+E52 -> 126 | H52: =F52-G52 -> 126
...

Sheet Dec-25
C2: CHUDLEIGH HOUSE SCHOOL STAFF LEAVE DAYS
C3: FOR THE MONTH OF FEBRUARY 2022
B4: NAME | C4: POSITION | D4: OPENING | E4: DAYS EARNED | F4: TOTAL | G4: DAYS TAKEN | H4: NET
A5: 1 | B5: ABBY PHIRI | D5: ='Nov-25'!H5 -> 41 | E5: 2 | F5: =D5+E5 -> 43 | H5: =F5-G5 -> 43
A6: 2 | B6: Margaret Mukondwa | C6: Executive Assistant | D6: ='Apr-25'!H6 -> 139 | E6: 2 | F6: =D6+E6 -> 141 | H6: =F6-G6 -> 141
A7: 3 | B7: mizzie Mutambo | C7: ass. Accountant | D7: 21 | E7: 2 | F7: =D7+E7 -> 23 | H7: =F7-G7 -> 23
A8: 4 | B8: Tembo Bertha | C8: teacher Primary | D8: 185 | E8: 2 | F8: =D8+E8 -> 187 | H8: =F8-G8 -> 187
A9: 5 | B9: Kamanugu Mriiam | C9: Teacher Primary | D9: ='Apr-25'!H9 -> 0 | E9: 2 | F9: =D9+E9 -> 2 | G9: 10 | H9: =F9-G9 -> -8
A10: 6 | B10: Chisenga Gillian Mwambela | C10: teacher Primary | D10: 88 | E10: 2 | F10: =D10+E10 -> 90 | G10: 2 | H10: =F10-G10 -> 88
A11: 7 | B11: Nambela Mercy | C11: teacher Primary | D11: 33 | E11: 2 | F11: =D11+E11 -> 35 | H11: =F11-G11 -> 35
A12: 8 | B12: Mutale Mirram | C12: teacher Primary | D12: 12 | E12: 2 | F12: =D12+E12 -> 14 | G12: 5 | H12: =F12-G12 -> 9
A13: 9 | B13: Zimba Francisca | C13: teacher Primary | D13: 26 | E13: 2 | F13: =D13+E13 -> 28 | G13: 10 | H13: =F13-G13 -> 18
A14: 10 | B14: Ireen Nachinga | C14: teacher Primary | D14: 42 | E14: 2 | F14: =D14+E14 -> 44 | G14: 5 | H14: =F14-G14 -> 39
A15: 11 | B15: Munyati Senitor | C15: PCELC - Teacher | D15: 22 | E15: 2 | F15: =D15+E15 -> 24 | G15: 5 | H15: =F15-G15 -> 19
A16: 12 | B16: Banda Mary | C16: PCELC- Teacher | D16: 43 | E16: 2 | F16: =D16+E16 -> 45 | H16: =F16-G16 -> 45
A17: 13 | B17: Mwanida Jere | C17: PCELC- Teacher | D17: ='Apr-25'!H17 -> -6 | E17: 2 | F17: =D17+E17 -> -4 | G17: 5 | H17: =F17-G17 -> -9
A18: 14 | B18: George Kakoma | C18: Cashier | D18: 36 | E18: 2 | F18: =D18+E18 -> 38 | G18: 5 | H18: =F18-G18 -> 33
A19: 15 | B19: Masebo Hudson | C19: School Bursar | D19: 27 | E19: 2 | F19: =D19+E19 -> 29 | H19: =F19-G19 -> 29
A20: 16 | B20: Nancy nanyangwe | C20: Cashier | D20: 43 | E20: 2 | F20: =D20+E20 -> 45 | H20: =F20-G20 -> 45
A21: 17 | B21: samuel Chinyama | C21: Teacher | D21: 45 | E21: 2 | F21: =D21+E21 -> 47 | G21: 6 | H21: =F21-G21 -> 41
A22: 18 | B22: besa Godfrey | C22: Senior Techer | D22: 74 | E22: 2 | F22: =D22+E22 -> 76 | G22: 4 | H22: =F22-G22 -> 72
A23: 19 | B23: Mario Kambani | C23: General Works | D23: 10 | E23: 2 | F23: =D23+E23 -> 12 | G23: 6 | H23: =F23-G23 -> 6
A24: 20 | B24: Josaya Milanzi | C24: Teacher | D24: 13 | E24: 2 | F24: =D24+E24 -> 15 | G24: 6 | H24: =F24-G24 -> 9
A25: 21 | B25: Timothy Phiri | C25: General Works | D25: 33 | E25: 2 | F25: =D25+E25 -> 35 | G25: 7 | H25: =F25-G25 -> 28
A26: 22 | B26: Winnie Sishwani | C26: Teacher Secondary | D26: 38 | E26: 2 | F26: =D26+E26 -> 40 | G26: 5 | H26: =F26-G26 -> 35
A27: 23 | B27: Valentine Zulu | C27: Teacher Secondary | D27: 29 | E27: 2 | F27: =D27+E27 -> 31 | G27: 6 | H27: =F27-G27 -> 25
A28: 24 | B28: Tembo Diana | C28: lib Assitant | D28: 34 | E28: 2 | F28: =D28+E28 -> 36 | G28: 5 | H28: =F28-G28 -> 31
A29: 25 | B29: Kikaba Obedieah | C29: Teacher Secondary | D29: 76 | E29: 2 | F29: =D29+E29 -> 78 | G29: 4 | H29: =F29-G29 -> 74
A30: 26 | B30: Anderson Ngulube | C30: Secondary | D30: 22 | E30: 2 | F30: =D30+E30 -> 24 | H30: =F30-G30 -> 24
A31: 27 | B31: fredrick Phiri | C31: Primary | D31: 9 | E31: 2 | F31: =D31+E31 -> 11 | G31: 13 | H31: =F31-G31 -> -2
A32: 28 | B32: kalongana Nyambe | C32: security | D32: 8 | E32: 2 | F32: =D32+E32 -> 10 | H32: =F32-G32 -> 10
A33: 29 | B33: Namakala Mackenzie | C33: Primary Head | D33: 4 | E33: 2 | F33: =D33+E33 -> 6 | G33: 10 | H33: =F33-G33 -> -4
A34: 30 | B34: Mashewa Alice | C34: Primary | D34: ='Apr-25'!H34 -> 0 | E34: 2 | F34: =D34+E34 -> 2 | H34: =F34-G34 -> 2
A35: 31 | B35: Rose Daka | C35: PCELC | D35: ='Apr-25'!H35 -> 7 | E35: 2 | F35: =D35+E35 -> 9 | G35: 15 | H35: =F35-G35 -> -6
A36: 32 | B36: priscilla Muluso | C36: primary | D36: 24 | E36: 2 | F36: =D36+E36 -> 26 | G36: 3 | H36: =F36-G36 -> 23
A37: 33 | B37: Banda Esther | C37: prmary | D37: 9 | E37: 2 | F37: =D37+E37 -> 11 | G37: 13 | H37: =F37-G37 -> -2
A38: 34 | B38: beatrice Kasuka | C38: General works | D38: 9 | E38: 2 | F38: =D38+E38 -> 11 | G38: 13 | H38: =F38-G38 -> -2
A39: 35 | B39: gwaba Mweemba | C39: Head Secondary | D39: 4 | E39: 2 | F39: =D39+E39 -> 6 | G39: 15 | H39: =F39-G39 -> -9
A40: 36 | B40: caleb Simuchimba | C40: Secondary | D40: 81 | E40: 2 | F40: =D40+E40 -> 83 | H40: =F40-G40 -> 83
A41: 37 | B41: Kabemba Kim Kabemba | C41: Primary | D41: ='Apr-25'!H41 -> 0 | E41: 2 | F41: =D41+E41 -> 2 | G41: 10 | H41: =F41-G41 -> -8
...
